Workbook

Sheet Assumptions
A1: NutraComply — Railway Hosting Cost Assumptions
A2: Blue = editable input | Yellow background = key assumption | Prices in USD
A4: Assumption | B4: Value | C4: Unit | D4: Source / Notes
A5: A. Railway Platform Pricing
A6: Railway Hobby Plan fee | B6: 5 | C6: $/month | D6: Source: Railway.app pricing, Mar 2026
A7: RAM price | B7: 0.000231 | C7: $/GB/min | D7: Source: Railway.app pricing, Mar 2026
A8: vCPU price | B8: 0.000463 | C8: $/vCPU/min | D8: Source: Railway.app pricing, Mar 2026
A9: Hours per month (avg) | B9: 720 | C9: hours | D9: 30 days × 24 hrs
A10: B. Railway Service Specifications
A11: Web App — RAM (GB) | B11: 1 | C11: GB | D11: PaddleOCR requires ≥1 GB RAM
A12: Web App — vCPU | B12: 0.5 | C12: vCPU | D12: Railway shared CPU default
A13: Celery Worker — RAM (GB) | B13: 0.5 | C13: GB | D13: Background processing service
A14: Celery Worker — vCPU | B14: 0.25 | C14: vCPU | D14: Railway default
A15: PostgreSQL — RAM (GB) | B15: 0.5 | C15: GB | D15: Railway PostgreSQL plugin
A16: PostgreSQL — vCPU | B16: 0.1 | C16: vCPU | D16: Railway PostgreSQL plugin
A17: Redis — RAM (GB) | B17: 0.25 | C17: GB | D17: Railway Redis plugin
A18: Redis — vCPU | B18: 0.05 | C18: vCPU | D18: Railway Redis plugin
A19: C. Network Egress
A20: Free egress per month | B20: 100 | C20: GB | D20: Source: Railway.app pricing, Mar 2026
A21: Overage price | B21: 0.1 | C21: $/GB | D21: Source: Railway.app pricing, Mar 2026
A22: Estimated egress — Month 1 | B22: 5 | C22: GB | D22: Assumption: low initial traffic
A23: Egress growth rate (MoM) | B23: 0.25 | C23: fraction | D23: Assumption: 25% MoM growth
A24: D. Usage Volume
A25: Label analyses — Month 1 | B25: 50 | C25: analyses | D25: Assumption: beta launch
A26: Analyses growth rate (MoM) | B26: 0.2 | C26: fraction | D26: Assumption: 20% MoM growth
A27: Email alerts — Month 1 | B27: 20 | C27: emails | D27: Assumption
A28: E. Google Gemini API (Flash)
A29: Tokens per analysis (blended) | B29: 5000 | C29: tokens | D29: Estimate: prompt + OCR text + response
A30: Input token price | B30: 0.075 | C30: $/1M tokens | D30: Source: Google AI Studio pricing, Mar 2026
A31: Output token price | B31: 0.3 | C31: $/1M tokens | D31: Source: Google AI Studio pricing, Mar 2026
A32: Input / output token split (input %) | B32: 0.7 | C32: fraction | D32: Assumption: 70% input tokens
A33: Free-tier analyses threshold | B33: 500 | C33: analyses/mo | D33: Gemini Flash free: 15 RPM; ample for early usage
A34: F. File Storage (Cloudflare R2)
A35: Average label file size | B35: 2 | C35: MB/file | D35: Assumption: typical PDF or image
A36: R2 free storage tier | B36: 10 | C36: GB | D36: Source: Cloudflare R2 pricing, Mar 2026
A37: R2 storage price (over free) | B37: 0.015 | C37: $/GB/month | D37: Source: Cloudflare R2 pricing, Mar 2026
A38: G. Brevo Email (SMTP)
A39: Brevo free tier (emails/month) | B39: 9000 | C39: emails | D39: Source: Brevo.com pricing, Mar 2026
A40: Brevo Starter plan cost (if exceeded) | B40: 25 | C40: $/month | D40: Source: Brevo.com pricing, Mar 2026
A41: H. Domain & Miscellaneous
...

Sheet Cost Model
A1: NutraComply — 6-Month Hosting Cost Model (Apr – Sep 2026)
A2: Blue = hardcoded input | Black = formula | Green = cross-sheet link | All figures in USD
A4: Cost Category | B4: Notes / Driver | C4: Apr 2026 | D4: May 2026 | E4: Jun 2026 | F4: Jul 2026 | G4: Aug 2026 | H4: Sep 2026 | I4: 6-Mo Total
A5: 1. Railway Infrastructure
A6: Platform Fee (Hobby Plan) | B6: Flat monthly fee | C6: =Assumptions!$B$6 | D6: =Assumptions!$B$6 | E6: =Assumptions!$B$6 | F6: =Assumptions!$B$6 | G6: =Assumptions!$B$6 | H6: =Assumptions!$B$6 | I6: =SUM(C6:H6)
A7: Web App Service | B7: RAM + CPU × 60 min × hrs/mo | C7: =(Assumptions!$B$11*Assumptions!$B$7+Assumptions!$B$12*Assumptions!$B$8)*60*Assumptions!$B$9 | D7: =(Assumptions!$B$11*Assumptions!$B$7+Assumptions!$B$12*Assumptions!$B$8)*60*Assumptions!$B$9 | E7: =(Assumptions!$B$11*Assumptions!$B$7+Assumptions!$B$12*Assumptions!$B$8)*60*Assumptions!$B$9 | F7: =(Assumptions!$B$11*Assumptions!$B$7+Assumptions!$B$12*Assumptions!$B$8)*60*Assumptions!$B$9 | G7: =(Assumptions!$B$11*Assumptions!$B$7+Assumptions!$B$12*Assumptions!$B$8)*60*Assumptions!$B$9 | H7: =(Assumptions!$B$11*Assumptions!$B$7+Assumptions!$B$12*Assumptions!$B$8)*60*Assumptions!$B$9 | I7: =SUM(C7:H7)
A8: PostgreSQL Database | B8: RAM + CPU × 60 min × hrs/mo | C8: =(Assumptions!$B$15*Assumptions!$B$7+Assumptions!$B$16*Assumptions!$B$8)*60*Assumptions!$B$9 | D8: =(Assumptions!$B$15*Assumptions!$B$7+Assumptions!$B$16*Assumptions!$B$8)*60*Assumptions!$B$9 | E8: =(Assumptions!$B$15*Assumptions!$B$7+Assumptions!$B$16*Assumptions!$B$8)*60*Assumptions!$B$9 | F8: =(Assumptions!$B$15*Assumptions!$B$7+Assumptions!$B$16*Assumptions!$B$8)*60*Assumptions!$B$9 | G8: =(Assumptions!$B$15*Assumptions!$B$7+Assumptions!$B$16*Assumptions!$B$8)*60*Assumptions!$B$9 | H8: =(Assumptions!$B$15*Assumptions!$B$7+Assumptions!$B$16*Assumptions!$B$8)*60*Assumptions!$B$9 | I8: =SUM(C8:H8)
A9: Redis Cache | B9: RAM + CPU × 60 min × hrs/mo | C9: =(Assumptions!$B$17*Assumptions!$B$7+Assumptions!$B$18*Assumptions!$B$8)*60*Assumptions!$B$9 | D9: =(Assumptions!$B$17*Assumptions!$B$7+Assumptions!$B$18*Assumptions!$B$8)*60*Assumptions!$B$9 | E9: =(Assumptions!$B$17*Assumptions!$B$7+Assumptions!$B$18*Assumptions!$B$8)*60*Assumptions!$B$9 | F9: =(Assumptions!$B$17*Assumptions!$B$7+Assumptions!$B$18*Assumptions!$B$8)*60*Assumptions!$B$9 | G9: =(Assumptions!$B$17*Assumptions!$B$7+Assumptions!$B$18*Assumptions!$B$8)*60*Assumptions!$B$9 | H9: =(Assumptions!$B$17*Assumptions!$B$7+Assumptions!$B$18*Assumptions!$B$8)*60*Assumptions!$B$9 | I9: =SUM(C9:H9)
A10: Celery Worker | B10: RAM + CPU × 60 min × hrs/mo | C10: =(Assumptions!$B$13*Assumptions!$B$7+Assumptions!$B$14*Assumptions!$B$8)*60*Assumptions!$B$9 | D10: =(Assumptions!$B$13*Assumptions!$B$7+Assumptions!$B$14*Assumptions!$B$8)*60*Assumptions!$B$9 | E10: =(Assumptions!$B$13*Assumptions!$B$7+Assumptions!$B$14*Assumptions!$B$8)*60*Assumptions!$B$9 | F10: =(Assumptions!$B$13*Assumptions!$B$7+Assumptions!$B$14*Assumptions!$B$8)*60*Assumptions!$B$9 | G10: =(Assumptions!$B$13*Assumptions!$B$7+Assumptions!$B$14*Assumptions!$B$8)*60*Assumptions!$B$9 | H10: =(Assumptions!$B$13*Assumptions!$B$7+Assumptions!$B$14*Assumptions!$B$8)*60*Assumptions!$B$9 | I10: =SUM(C10:H10)
A11: Network Egress | B11: MAX(0, GB - 100 GB free) × $0.10/GB | C11: =MAX(0,Assumptions!$B$22-Assumptions!$B$20)*Assumptions!$B$21 | D11: =MAX(0,(Assumptions!$B$22*(1+Assumptions!$B$23)^1)-Assumptions!$B$20)*Assumptions!$B$21 | E11: =MAX(0,(Assumptions!$B$22*(1+Assumptions!$B$23)^2)-Assumptions!$B$20)*Assumptions!$B$21 | F11: =MAX(0,(Assumptions!$B$22*(1+Assumptions!$B$23)^3)-Assumptions!$B$20)*Assumptions!$B$21 | G11: =MAX(0,(Assumptions!$B$22*(1+Assumptions!$B$23)^4)-Assumptions!$B$20)*Assumptions!$B$21 | H11: =MAX(0,(Assumptions!$B$22*(1+Assumptions!$B$23)^5)-Assumptions!$B$20)*Assumptions!$B$21 | I11: =SUM(C11:H11)
A12: Subtotal — Railway Infrastructure | C12: =SUM(C6+C7+C8+C9+C10+C11) | D12: =SUM(D6+D7+D8+D9+D10+D11) | E12: =SUM(E6+E7+E8+E9+E10+E11) | F12: =SUM(F6+F7+F8+F9+F10+F11) | G12: =SUM(G6+G7+G8+G9+G10+G11) | H12: =SUM(H6+H7+H8+H9+H10+H11) | I12: =SUM(C12:H12)
A14: 2. APIs & Third-Party Services
A15: Google Gemini API (Flash) | B15: MAX(0, analyses - 500 free) × token cost | C15: =MAX(0,Assumptions!$B$25-Assumptions!$B$33)*((Assumptions!$B$32*Assumptions!$B$30+(1-Assumptions!$B$32)*Assumptions!$B$31)/1000000*Assumptions!$B$29) | D15: =MAX(0,(Assumptions!$B$25*(1+Assumptions!$B$26)^1)-Assumptions!$B$33)*((Assumptions!$B$32*Assumptions!$B$30+(1-Assumptions!$B$32)*Assumptions!$B$31)/1000000*Assumptions!$B$29) | E15: =MAX(0,(Assumptions!$B$25*(1+Assumptions!$B$26)^2)-Assumptions!$B$33)*((Assumptions!$B$32*Assumptions!$B$30+(1-Assumptions!$B$32)*Assumptions!$B$31)/1000000*Assumptions!$B$29) | F15: =MAX(0,(Assumptions!$B$25*(1+Assumptions!$B$26)^3)-Assumptions!$B$33)*((Assumptions!$B$32*Assumptions!$B$30+(1-Assumptions!$B$32)*Assumptions!$B$31)/1000000*Assumptions!$B$29) | G15: =MAX(0,(Assumptions!$B$25*(1+Assumptions!$B$26)^4)-Assumptions!$B$33)*((Assumptions!$B$32*Assumptions!$B$30+(1-Assumptions!$B$32)*Assumptions!$B$31)/1000000*Assumptions!$B$29) | H15: =MAX(0,(Assumptions!$B$25*(1+Assumptions!$B$26)^5)-Assumptions!$B$33)*((Assumptions!$B$32*Assumptions!$B$30+(1-Assumptions!$B$32)*Assumptions!$B$31)/1000000*Assumptions!$B$29) | I15: =SUM(C15:H15)
A16: Brevo SMTP (Email Alerts) | B16: Free ≤9,000 emails/mo; $25/mo if exceeded | C16: =IF(Assumptions!$B$27>Assumptions!$B$39,Assumptions!$B$40,0) | D16: =IF((Assumptions!$B$27*(1+Assumptions!$B$26)^1)>Assumptions!$B$39,Assumptions!$B$40,0) | E16: =IF((Assumptions!$B$27*(1+Assumptions!$B$26)^2)>Assumptions!$B$39,Assumptions!$B$40,0) | F16: =IF((Assumptions!$B$27*(1+Assumptions!$B$26)^3)>Assumptions!$B$39,Assumptions!$B$40,0) | G16: =IF((Assumptions!$B$27*(1+Assumptions!$B$26)^4)>Assumptions!$B$39,Assumptions!$B$40,0) | H16: =IF((Assumptions!$B$27*(1+Assumptions!$B$26)^5)>Assumptions!$B$39,Assumptions!$B$40,0) | I16: =SUM(C16:H16)
A17: Subtotal — APIs & Services | C17: =SUM(C15+C16) | D17: =SUM(D15+D16) | E17: =SUM(E15+E16) | F17: =SUM(F15+F16) | G17: =SUM(G15+G16) | H17: =SUM(H15+H16) | I17: =SUM(C17:H17)
A19: 3. File Storage (Cloudflare R2)
A20: Cloudflare R2 Storage | B20: Cumulative uploads over 10 GB free tier | C20: =MAX(0,((Assumptions!$B$25*((1+Assumptions!$B$26)^1-1)/Assumptions!$B$26)*Assumptions!$B$35/1024)-Assumptions!$B$36)*Assumptions!$B$37 | D20: =MAX(0,((Assumptions!$B$25*((1+Assumptions!$B$26)^2-1)/Assumptions!$B$26)*Assumptions!$B$35/1024)-Assumptions!$B$36)*Assumptions!$B$37 | E20: =MAX(0,((Assumptions!$B$25*((1+Assumptions!$B$26)^3-1)/Assumptions!$B$26)*Assumptions!$B$35/1024)-Assumptions!$B$36)*Assumptions!$B$37 | F20: =MAX(0,((Assumptions!$B$25*((1+Assumptions!$B$26)^4-1)/Assumptions!$B$26)*Assumptions!$B$35/1024)-Assumptions!$B$36)*Assumptions!$B$37 | G20: =MAX(0,((Assumptions!$B$25*((1+Assumptions!$B$26)^5-1)/Assumptions!$B$26)*Assumptions!$B$35/1024)-Assumptions!$B$36)*Assumptions!$B$37 | H20: =MAX(0,((Assumptions!$B$25*((1+Assumptions!$B$26)^6-1)/Assumptions!$B$26)*Assumptions!$B$35/1024)-Assumptions!$B$36)*Assumptions!$B$37 | I20: =SUM(C20:H20)
A21: Subtotal — Storage | C21: =SUM(C20) | D21: =SUM(D20) | E21: =SUM(E20) | F21: =SUM(F20) | G21: =SUM(G20) | H21: =SUM(H20) | I21: =SUM(C21:H21)
A23: 4. Domain & Miscellaneous
A24: Domain Registration | B24: Annual fee billed upfront in Month 1 | C24: =Assumptions!$B$42 | D24: =0 | E24: =0 | F24: =0 | G24: =0 | H24: =0 | I24: =SUM(C24:H24)
A25: Monitoring (Sentry) | B25: Free tier for hobby projects | C25: =Assumptions!$B$43 | D25: =Assumptions!$B$43 | E25: =Assumptions!$B$43 | F25: =Assumptions!$B$43 | G25: =Assumptions!$B$43 | H25: =Assumptions!$B$43 | I25: =SUM(C25:H25)
A26: Subtotal — Domain & Misc | C26: =SUM(C24+C25) | D26: =SUM(D24+D25) | E26: =SUM(E24+E25) | F26: =SUM(F24+F25) | G26: =SUM(G24+G25) | H26: =SUM(H24+H25) | I26: =SUM(C26:H26)
A28: TOTAL MONTHLY COST ($) | C28: =C12+C17+C21+C26 | D28: =D12+D17+D21+D26 | E28: =E12+E17+E21+E26 | F28: =F12+F17+F21+F26 | G28: =G12+G17+G21+G26 | H28: =H12+H17+H21+H26 | I28: =SUM(C28:H28)
A29: Month-over-Month Change ($) | B29: Change vs. prior month | C29: — | D29: =D28-C28 | E29: =E28-D28 | F29: =F28-E28 | G29: =G28-F28 | H29: =H28-G28
A30: Month-over-Month Change (%) | B30: % change vs. prior month | C30: — | D30: =IF(C28=0,0,(D28-C28)/C28) | E30: =IF(D28=0,0,(E28-D28)/D28) | F30: =IF(E28=0,0,(F28-E28)/E28) | G30: =IF(F28=0,0,(G28-F28)/F28) | H30: =IF(G28=0,0,(H28-G28)/G28)
A32: Usage Reference (non-cost)
A33: Label Analyses (volume) | B33: Monthly analyses estimate (20% MoM growth) | C33: =Assumptions!$B$25 | D33: =Assumptions!$B$25*(1+Assumptions!$B$26)^1 | E33: =Assumptions!$B$25*(1+Assumptions!$B$26)^2 | F33: =Assumptions!$B$25*(1+Assumptions!$B$26)^3 | G33: =Assumptions!$B$25*(1+Assumptions!$B$26)^4 | H33: =Assumptions!$B$25*(1+Assumptions!$B$26)^5 | I33: =SUM(C33:H33)
A34: Cost per Analysis ($) | B34: Total cost ÷ analyses volume | C34: =IF(C33=0,0,C28/C33) | D34: =IF(D33=0,0,D28/D33) | E34: =IF(E33=0,0,E28/E33) | F34: =IF(F33=0,0,F28/F33) | G34: =IF(G33=0,0,G28/G33) | H34: =IF(H33=0,0,H28/H33)
